#include <iostream>
#include <vector>
#include <stdexcept>

using namespace std;

double divide(double,double);

int main(){
	
	double n1, n2;
	
	cin >> n1 >> n2;
	
	try{
		cout << divide(n1,n2);
	}catch(const char* e){     //Jogando a mensagem de exceção dentro da função divide para nosso catch
		cout << "Erro: " << e << endl;
	}
	
	return 0;
}

double divide(double n10, double n20){
	if(n20==0){
		throw "Erro de divisao por zero.";     //Fazendo a mensagem de exceção
	}
	if(n10>=10){
		throw "N1 precisa ser menor que 10.";     //Usando uma exceção que é usualmente aceitável, porém foi feita pelo programador
	}
	return n10/n20;
}



/*
	vector<int>num(5);
	
	try{     //Ele vai gerar uma exceção porque esse erro foi tratado, ele foi para a exceção no catch
		num.at(6)=10;
		cout << num[0] << endl;
	}catch(exception& e){     //Colocando o bloco de tratamento no catch
		cout << "Erro: " << e.what() << endl;     //e.what é para mostrar qual o erro que foi gerado na rotina
	}
*/
